[2025-06-30T23:04:20.224+0000] {local_task_job_runner.py:123} INFO - ::group::Pre task execution logs
[2025-06-30T23:04:20.242+0000] {taskinstance.py:2613} INFO - Dependencies all met for dep_context=non-requeueable deps ti=<TaskInstance: youtube_comments_etl_pipeline.extract_youtube_data manual__2025-06-30T23:03:38.834806+00:00 [queued]>
[2025-06-30T23:04:20.251+0000] {taskinstance.py:2613} INFO - Dependencies all met for dep_context=requeueable deps ti=<TaskInstance: youtube_comments_etl_pipeline.extract_youtube_data manual__2025-06-30T23:03:38.834806+00:00 [queued]>
[2025-06-30T23:04:20.252+0000] {taskinstance.py:2866} INFO - Starting attempt 1 of 1
[2025-06-30T23:04:20.269+0000] {taskinstance.py:2889} INFO - Executing <Task(_PythonDecoratedOperator): extract_youtube_data> on 2025-06-30 23:03:38.834806+00:00
[2025-06-30T23:04:20.277+0000] {warnings.py:112} WARNING - /home/***/.local/lib/python3.12/site-packages/***/task/task_runner/standard_task_runner.py:70: DeprecationWarning: This process (pid=125) is multi-threaded, use of fork() may lead to deadlocks in the child.
  pid = os.fork()

[2025-06-30T23:04:20.279+0000] {standard_task_runner.py:72} INFO - Started process 127 to run task
[2025-06-30T23:04:20.279+0000] {standard_task_runner.py:104} INFO - Running: ['***', 'tasks', 'run', 'youtube_comments_etl_pipeline', 'extract_youtube_data', 'manual__2025-06-30T23:03:38.834806+00:00', '--job-id', '1118', '--raw', '--subdir', 'DAGS_FOLDER/yt_comments_dag.py', '--cfg-path', '/tmp/tmpba454u1d']
[2025-06-30T23:04:20.280+0000] {standard_task_runner.py:105} INFO - Job 1118: Subtask extract_youtube_data
[2025-06-30T23:04:20.341+0000] {task_command.py:467} INFO - Running <TaskInstance: youtube_comments_etl_pipeline.extract_youtube_data manual__2025-06-30T23:03:38.834806+00:00 [running]> on host cb417f028d7b
[2025-06-30T23:04:20.707+0000] {taskinstance.py:3132} INFO - Exporting env vars: AIRFLOW_CTX_DAG_OWNER='***' AIRFLOW_CTX_DAG_ID='youtube_comments_etl_pipeline' AIRFLOW_CTX_TASK_ID='extract_youtube_data' AIRFLOW_CTX_EXECUTION_DATE='2025-06-30T23:03:38.834806+00:00' AIRFLOW_CTX_TRY_NUMBER='1' AIRFLOW_CTX_DAG_RUN_ID='manual__2025-06-30T23:03:38.834806+00:00'
[2025-06-30T23:04:20.708+0000] {logging_mixin.py:190} INFO - Task instance is in running state
[2025-06-30T23:04:20.708+0000] {logging_mixin.py:190} INFO -  Previous state of the Task instance: queued
[2025-06-30T23:04:20.709+0000] {logging_mixin.py:190} INFO - Current task name:extract_youtube_data state:running start_date:2025-06-30 23:04:20.243454+00:00
[2025-06-30T23:04:20.710+0000] {logging_mixin.py:190} INFO - Dag name:youtube_comments_etl_pipeline and current dag run status:running
[2025-06-30T23:04:20.710+0000] {taskinstance.py:731} INFO - ::endgroup::
[2025-06-30T23:04:20.712+0000] {logging_mixin.py:190} INFO - os.getenv(ytb_api):2 None
[2025-06-30T23:04:20.716+0000] {__init__.py:49} INFO - file_cache is only supported with oauth2client<4.0.0
[2025-06-30T23:04:20.724+0000] {_metadata.py:142} WARNING - Compute Engine Metadata server unavailable on attempt 1 of 3. Reason: [Errno 111] Connection refused
[2025-06-30T23:04:21.763+0000] {_metadata.py:142} WARNING - Compute Engine Metadata server unavailable on attempt 2 of 3. Reason: [Errno 111] Connection refused
[2025-06-30T23:04:23.940+0000] {_metadata.py:142} WARNING - Compute Engine Metadata server unavailable on attempt 3 of 3. Reason: [Errno 111] Connection refused
[2025-06-30T23:04:23.941+0000] {_default.py:340} WARNING - Authentication failed using Compute Engine authentication due to unavailable metadata server.
[2025-06-30T23:04:23.942+0000] {taskinstance.py:3311} ERROR - Task failed with exception
Traceback (most recent call last):
  File "/home/airflow/.local/lib/python3.12/site-packages/airflow/models/taskinstance.py", line 767, in _execute_task
    result = _execute_callable(context=context, **execute_callable_kwargs)
             ^^^^^^^^^^^^^^^^^^^^^^^^^^^^^^^^^^^^^^^^^^^^^^^^^^^^^^^^^^^^^
  File "/home/airflow/.local/lib/python3.12/site-packages/airflow/models/taskinstance.py", line 733, in _execute_callable
    return ExecutionCallableRunner(
           ^^^^^^^^^^^^^^^^^^^^^^^^
  File "/home/airflow/.local/lib/python3.12/site-packages/airflow/utils/operator_helpers.py", line 252, in run
    return self.func(*args, **kwargs)
           ^^^^^^^^^^^^^^^^^^^^^^^^^^
  File "/home/airflow/.local/lib/python3.12/site-packages/airflow/models/baseoperator.py", line 422, in wrapper
    return func(self, *args, **kwargs)
           ^^^^^^^^^^^^^^^^^^^^^^^^^^^
  File "/home/airflow/.local/lib/python3.12/site-packages/airflow/decorators/base.py", line 266, in execute
    return_value = super().execute(context)
                   ^^^^^^^^^^^^^^^^^^^^^^^^
  File "/home/airflow/.local/lib/python3.12/site-packages/airflow/models/baseoperator.py", line 422, in wrapper
    return func(self, *args, **kwargs)
           ^^^^^^^^^^^^^^^^^^^^^^^^^^^
  File "/home/airflow/.local/lib/python3.12/site-packages/airflow/operators/python.py", line 238, in execute
    return_value = self.execute_callable()
                   ^^^^^^^^^^^^^^^^^^^^^^^
  File "/home/airflow/.local/lib/python3.12/site-packages/airflow/operators/python.py", line 256, in execute_callable
    return runner.run(*self.op_args, **self.op_kwargs)
           ^^^^^^^^^^^^^^^^^^^^^^^^^^^^^^^^^^^^^^^^^^^
  File "/home/airflow/.local/lib/python3.12/site-packages/airflow/utils/operator_helpers.py", line 252, in run
    return self.func(*args, **kwargs)
           ^^^^^^^^^^^^^^^^^^^^^^^^^^
  File "/opt/airflow/dags/yt_comments_dag.py", line 48, in extract_youtube_data
    youtube = googleapiclient.discovery.build(
              ^^^^^^^^^^^^^^^^^^^^^^^^^^^^^^^^
  File "/home/airflow/.local/lib/python3.12/site-packages/googleapiclient/_helpers.py", line 130, in positional_wrapper
    return wrapped(*args, **kwargs)
           ^^^^^^^^^^^^^^^^^^^^^^^^
  File "/home/airflow/.local/lib/python3.12/site-packages/googleapiclient/discovery.py", line 315, in build
    service = build_from_document(
              ^^^^^^^^^^^^^^^^^^^^
  File "/home/airflow/.local/lib/python3.12/site-packages/googleapiclient/_helpers.py", line 130, in positional_wrapper
    return wrapped(*args, **kwargs)
           ^^^^^^^^^^^^^^^^^^^^^^^^
  File "/home/airflow/.local/lib/python3.12/site-packages/googleapiclient/discovery.py", line 616, in build_from_document
    credentials = _auth.default_credentials(
                  ^^^^^^^^^^^^^^^^^^^^^^^^^^
  File "/home/airflow/.local/lib/python3.12/site-packages/googleapiclient/_auth.py", line 57, in default_credentials
    credentials, _ = google.auth.default(
                     ^^^^^^^^^^^^^^^^^^^^
  File "/home/airflow/.local/lib/python3.12/site-packages/google/auth/_default.py", line 697, in default
    raise exceptions.DefaultCredentialsError(_CLOUD_SDK_MISSING_CREDENTIALS)
google.auth.exceptions.DefaultCredentialsError: Your default credentials were not found. To set up Application Default Credentials, see https://cloud.google.com/docs/authentication/external/set-up-adc for more information.
[2025-06-30T23:04:23.960+0000] {logging_mixin.py:190} INFO - Task instance in failure state
[2025-06-30T23:04:23.961+0000] {logging_mixin.py:190} INFO - Task start:2025-06-30 23:04:20.243454+00:00 end:2025-06-30 23:04:23.960402+00:00 duration:3.716948
[2025-06-30T23:04:23.962+0000] {logging_mixin.py:190} INFO - Task:<Task(_PythonDecoratedOperator): extract_youtube_data> dag:<DAG: youtube_comments_etl_pipeline> dagrun:<DagRun youtube_comments_etl_pipeline @ 2025-06-30 23:03:38.834806+00:00: manual__2025-06-30T23:03:38.834806+00:00, state:running, queued_at: 2025-06-30 23:03:38.853938+00:00. externally triggered: True>
[2025-06-30T23:04:23.963+0000] {logging_mixin.py:190} INFO - Failure caused by Your default credentials were not found. To set up Application Default Credentials, see https://cloud.google.com/docs/authentication/external/set-up-adc for more information.
[2025-06-30T23:04:23.963+0000] {taskinstance.py:1225} INFO - Marking task as FAILED. dag_id=youtube_comments_etl_pipeline, task_id=extract_youtube_data, run_id=manual__2025-06-30T23:03:38.834806+00:00, execution_date=20250630T230338, start_date=20250630T230420, end_date=20250630T230423
[2025-06-30T23:04:23.986+0000] {taskinstance.py:340} INFO - ::group::Post task execution logs
[2025-06-30T23:04:23.987+0000] {standard_task_runner.py:124} ERROR - Failed to execute job 1118 for task extract_youtube_data (Your default credentials were not found. To set up Application Default Credentials, see https://cloud.google.com/docs/authentication/external/set-up-adc for more information.; 127)
Traceback (most recent call last):
  File "/home/airflow/.local/lib/python3.12/site-packages/airflow/task/task_runner/standard_task_runner.py", line 117, in _start_by_fork
    ret = args.func(args, dag=self.dag)
          ^^^^^^^^^^^^^^^^^^^^^^^^^^^^^
  File "/home/airflow/.local/lib/python3.12/site-packages/airflow/cli/cli_config.py", line 49, in command
    return func(*args, **kwargs)
           ^^^^^^^^^^^^^^^^^^^^^
  File "/home/airflow/.local/lib/python3.12/site-packages/airflow/utils/cli.py", line 116, in wrapper
    return f(*args, **kwargs)
           ^^^^^^^^^^^^^^^^^^
  File "/home/airflow/.local/lib/python3.12/site-packages/airflow/cli/commands/task_command.py", line 483, in task_run
    task_return_code = _run_task_by_selected_method(args, _dag, ti)
                       ^^^^^^^^^^^^^^^^^^^^^^^^^^^^^^^^^^^^^^^^^^^^
  File "/home/airflow/.local/lib/python3.12/site-packages/airflow/cli/commands/task_command.py", line 256, in _run_task_by_selected_method
    return _run_raw_task(args, ti)
           ^^^^^^^^^^^^^^^^^^^^^^^
  File "/home/airflow/.local/lib/python3.12/site-packages/airflow/cli/commands/task_command.py", line 341, in _run_raw_task
    return ti._run_raw_task(
           ^^^^^^^^^^^^^^^^^
  File "/home/airflow/.local/lib/python3.12/site-packages/airflow/utils/session.py", line 97, in wrapper
    return func(*args, session=session, **kwargs)
           ^^^^^^^^^^^^^^^^^^^^^^^^^^^^^^^^^^^^^^
  File "/home/airflow/.local/lib/python3.12/site-packages/airflow/models/taskinstance.py", line 3005, in _run_raw_task
    return _run_raw_task(
           ^^^^^^^^^^^^^^
  File "/home/airflow/.local/lib/python3.12/site-packages/airflow/models/taskinstance.py", line 273, in _run_raw_task
    TaskInstance._execute_task_with_callbacks(
  File "/home/airflow/.local/lib/python3.12/site-packages/airflow/models/taskinstance.py", line 3159, in _execute_task_with_callbacks
    result = self._execute_task(context, task_orig)
             ^^^^^^^^^^^^^^^^^^^^^^^^^^^^^^^^^^^^^^
  File "/home/airflow/.local/lib/python3.12/site-packages/airflow/models/taskinstance.py", line 3183, in _execute_task
    return _execute_task(self, context, task_orig)
           ^^^^^^^^^^^^^^^^^^^^^^^^^^^^^^^^^^^^^^^
  File "/home/airflow/.local/lib/python3.12/site-packages/airflow/models/taskinstance.py", line 767, in _execute_task
    result = _execute_callable(context=context, **execute_callable_kwargs)
             ^^^^^^^^^^^^^^^^^^^^^^^^^^^^^^^^^^^^^^^^^^^^^^^^^^^^^^^^^^^^^
  File "/home/airflow/.local/lib/python3.12/site-packages/airflow/models/taskinstance.py", line 733, in _execute_callable
    return ExecutionCallableRunner(
           ^^^^^^^^^^^^^^^^^^^^^^^^
  File "/home/airflow/.local/lib/python3.12/site-packages/airflow/utils/operator_helpers.py", line 252, in run
    return self.func(*args, **kwargs)
           ^^^^^^^^^^^^^^^^^^^^^^^^^^
  File "/home/airflow/.local/lib/python3.12/site-packages/airflow/models/baseoperator.py", line 422, in wrapper
    return func(self, *args, **kwargs)
           ^^^^^^^^^^^^^^^^^^^^^^^^^^^
  File "/home/airflow/.local/lib/python3.12/site-packages/airflow/decorators/base.py", line 266, in execute
    return_value = super().execute(context)
                   ^^^^^^^^^^^^^^^^^^^^^^^^
  File "/home/airflow/.local/lib/python3.12/site-packages/airflow/models/baseoperator.py", line 422, in wrapper
    return func(self, *args, **kwargs)
           ^^^^^^^^^^^^^^^^^^^^^^^^^^^
  File "/home/airflow/.local/lib/python3.12/site-packages/airflow/operators/python.py", line 238, in execute
    return_value = self.execute_callable()
                   ^^^^^^^^^^^^^^^^^^^^^^^
  File "/home/airflow/.local/lib/python3.12/site-packages/airflow/operators/python.py", line 256, in execute_callable
    return runner.run(*self.op_args, **self.op_kwargs)
           ^^^^^^^^^^^^^^^^^^^^^^^^^^^^^^^^^^^^^^^^^^^
  File "/home/airflow/.local/lib/python3.12/site-packages/airflow/utils/operator_helpers.py", line 252, in run
    return self.func(*args, **kwargs)
           ^^^^^^^^^^^^^^^^^^^^^^^^^^
  File "/opt/airflow/dags/yt_comments_dag.py", line 48, in extract_youtube_data
    youtube = googleapiclient.discovery.build(
              ^^^^^^^^^^^^^^^^^^^^^^^^^^^^^^^^
  File "/home/airflow/.local/lib/python3.12/site-packages/googleapiclient/_helpers.py", line 130, in positional_wrapper
    return wrapped(*args, **kwargs)
           ^^^^^^^^^^^^^^^^^^^^^^^^
  File "/home/airflow/.local/lib/python3.12/site-packages/googleapiclient/discovery.py", line 315, in build
    service = build_from_document(
              ^^^^^^^^^^^^^^^^^^^^
  File "/home/airflow/.local/lib/python3.12/site-packages/googleapiclient/_helpers.py", line 130, in positional_wrapper
    return wrapped(*args, **kwargs)
           ^^^^^^^^^^^^^^^^^^^^^^^^
  File "/home/airflow/.local/lib/python3.12/site-packages/googleapiclient/discovery.py", line 616, in build_from_document
    credentials = _auth.default_credentials(
                  ^^^^^^^^^^^^^^^^^^^^^^^^^^
  File "/home/airflow/.local/lib/python3.12/site-packages/googleapiclient/_auth.py", line 57, in default_credentials
    credentials, _ = google.auth.default(
                     ^^^^^^^^^^^^^^^^^^^^
  File "/home/airflow/.local/lib/python3.12/site-packages/google/auth/_default.py", line 697, in default
    raise exceptions.DefaultCredentialsError(_CLOUD_SDK_MISSING_CREDENTIALS)
google.auth.exceptions.DefaultCredentialsError: Your default credentials were not found. To set up Application Default Credentials, see https://cloud.google.com/docs/authentication/external/set-up-adc for more information.
[2025-06-30T23:04:24.028+0000] {local_task_job_runner.py:266} INFO - Task exited with return code 1
[2025-06-30T23:04:24.061+0000] {taskinstance.py:3895} INFO - 0 downstream tasks scheduled from follow-on schedule check
[2025-06-30T23:04:24.071+0000] {local_task_job_runner.py:245} INFO - ::endgroup::
